<?xml version="1.0"?>
<robot name="D:/ROBO Games 2025/robo_games_2025/Second round/Robot.urdf" xmlns:xacro="http://ros.org/wiki/xacro">
  <link name="base_link">
    <visual>
      <origin xyz="0 0 0.03" rpy="0 0 0"/>
      <geometry>
        <cylinder radius="0.04" length="0.05"/>
      </geometry>
    </visual>
    <collision>
      <origin xyz="0 0 0.03" rpy="0 0 0"/>
      <geometry>
        <cylinder radius="0.04" length="0.05"/>
      </geometry>
    </collision>
  </link>
  <link name="solid(2)">
    <visual>
      <geometry>
        <sphere radius="0.005"/>
      </geometry>
    </visual>
    <collision>
      <geometry>
        <sphere radius="0.005"/>
      </geometry>
    </collision>
  </link>
  <joint name="base_link_solid(2)_joint" type="fixed">
    <parent link="base_link"/>
    <child link="solid(2)"/>
    <origin xyz="0 0.04 0.005" rpy="0 -1.570795 0"/>
  </joint>
  <joint name="right wheel motor" type="continuous">
    <parent link="base_link"/>
    <child link="solid(1)"/>
    <axis xyz="-0.000004 0 1"/>
    <limit effort="10" velocity="10"/>
    <origin xyz="0.045 -0.01 0.0125" rpy="1.570748 -1.495638 1.570845"/>
  </joint>
  <link name="solid(1)">
    <visual>
      <geometry>
        <cylinder radius="0.0125" length="0.01"/>
      </geometry>
    </visual>
    <collision>
      <geometry>
        <cylinder radius="0.0125" length="0.01"/>
      </geometry>
    </collision>
  </link>
  <joint name="left wheel motor" type="continuous">
    <parent link="base_link"/>
    <child link="solid"/>
    <axis xyz="0.000003 -0.000001 -1"/>
    <limit effort="10" velocity="10"/>
    <origin xyz="-0.045 -0.01 0.0125" rpy="1.570794 -0.870629 -1.570792"/>
  </joint>
  <link name="solid">
    <visual>
      <geometry>
        <cylinder radius="0.0125" length="0.01"/>
      </geometry>
    </visual>
    <collision>
      <geometry>
        <cylinder radius="0.0125" length="0.01"/>
      </geometry>
    </collision>
  </link>
  <link name="sharp_front_right">
    <visual>
      <origin xyz="-0.0052 -0.0102 0" rpy="0 0 0"/>
      <geometry>
        <box size="0.01 0.03 0.0087"/>
      </geometry>
    </visual>
    <collision>
      <origin xyz="-0.0052 -0.0102 0" rpy="0 0 0"/>
      <geometry>
        <box size="0.01 0.03 0.0087"/>
      </geometry>
    </collision>
    <visual>
      <origin xyz="-0.0109 -0.0102 0" rpy="0 0 0"/>
      <geometry>
        <box size="0.0094 0.03 0.0131"/>
      </geometry>
    </visual>
    <collision>
      <origin xyz="-0.0109 -0.0102 0" rpy="0 0 0"/>
      <geometry>
        <box size="0.0094 0.03 0.0131"/>
      </geometry>
    </collision>
    <visual>
      <origin xyz="-0.0144 -0.0102 0" rpy="0 0 0"/>
      <geometry>
        <box size="0.0023 0.0445 0.0077"/>
      </geometry>
    </visual>
    <collision>
      <origin xyz="-0.0144 -0.0102 0" rpy="0 0 0"/>
      <geometry>
        <box size="0.0023 0.0445 0.0077"/>
      </geometry>
    </collision>
  </link>
  <joint name="base_link_sharp_front_right_joint" type="fixed">
    <parent link="base_link"/>
    <child link="sharp_front_right"/>
    <origin xyz="0.04 0.03 0.02" rpy="-1.570795 0.000002 1.570795"/>
  </joint>
  <link name="sharp_front_left">
    <visual>
      <origin xyz="-0.0052 -0.0102 0" rpy="0 0 0"/>
      <geometry>
        <box size="0.01 0.03 0.0087"/>
      </geometry>
    </visual>
    <collision>
      <origin xyz="-0.0052 -0.0102 0" rpy="0 0 0"/>
      <geometry>
        <box size="0.01 0.03 0.0087"/>
      </geometry>
    </collision>
    <visual>
      <origin xyz="-0.0109 -0.0102 0" rpy="0 0 0"/>
      <geometry>
        <box size="0.0094 0.03 0.0131"/>
      </geometry>
    </visual>
    <collision>
      <origin xyz="-0.0109 -0.0102 0" rpy="0 0 0"/>
      <geometry>
        <box size="0.0094 0.03 0.0131"/>
      </geometry>
    </collision>
    <visual>
      <origin xyz="-0.0144 -0.0102 0" rpy="0 0 0"/>
      <geometry>
        <box size="0.0023 0.0445 0.0077"/>
      </geometry>
    </visual>
    <collision>
      <origin xyz="-0.0144 -0.0102 0" rpy="0 0 0"/>
      <geometry>
        <box size="0.0023 0.0445 0.0077"/>
      </geometry>
    </collision>
  </link>
  <joint name="base_link_sharp_front_left_joint" type="fixed">
    <parent link="base_link"/>
    <child link="sharp_front_left"/>
    <origin xyz="-0.04 0.03 0.02" rpy="-1.570796 0.000004 1.570793"/>
  </joint>
  <link name="sharp_front">
    <visual>
      <origin xyz="-0.0052 -0.0102 0" rpy="0 0 0"/>
      <geometry>
        <box size="0.01 0.03 0.0087"/>
      </geometry>
    </visual>
    <collision>
      <origin xyz="-0.0052 -0.0102 0" rpy="0 0 0"/>
      <geometry>
        <box size="0.01 0.03 0.0087"/>
      </geometry>
    </collision>
    <visual>
      <origin xyz="-0.0109 -0.0102 0" rpy="0 0 0"/>
      <geometry>
        <box size="0.0094 0.03 0.0131"/>
      </geometry>
    </visual>
    <collision>
      <origin xyz="-0.0109 -0.0102 0" rpy="0 0 0"/>
      <geometry>
        <box size="0.0094 0.03 0.0131"/>
      </geometry>
    </collision>
    <visual>
      <origin xyz="-0.0144 -0.0102 0" rpy="0 0 0"/>
      <geometry>
        <box size="0.0023 0.0445 0.0077"/>
      </geometry>
    </visual>
    <collision>
      <origin xyz="-0.0144 -0.0102 0" rpy="0 0 0"/>
      <geometry>
        <box size="0.0023 0.0445 0.0077"/>
      </geometry>
    </collision>
  </link>
  <joint name="base_link_sharp_front_joint" type="fixed">
    <parent link="base_link"/>
    <child link="sharp_front"/>
    <origin xyz="0 0.03 0.04" rpy="1.570798 -0.000002 1.570801"/>
  </joint>
  <link name="sharp_right">
    <visual>
      <origin xyz="-0.0052 -0.0102 0" rpy="0 0 0"/>
      <geometry>
        <box size="0.01 0.03 0.0087"/>
      </geometry>
    </visual>
    <collision>
      <origin xyz="-0.0052 -0.0102 0" rpy="0 0 0"/>
      <geometry>
        <box size="0.01 0.03 0.0087"/>
      </geometry>
    </collision>
    <visual>
      <origin xyz="-0.0109 -0.0102 0" rpy="0 0 0"/>
      <geometry>
        <box size="0.0094 0.03 0.0131"/>
      </geometry>
    </visual>
    <collision>
      <origin xyz="-0.0109 -0.0102 0" rpy="0 0 0"/>
      <geometry>
        <box size="0.0094 0.03 0.0131"/>
      </geometry>
    </collision>
    <visual>
      <origin xyz="-0.0144 -0.0102 0" rpy="0 0 0"/>
      <geometry>
        <box size="0.0023 0.0445 0.0077"/>
      </geometry>
    </visual>
    <collision>
      <origin xyz="-0.0144 -0.0102 0" rpy="0 0 0"/>
      <geometry>
        <box size="0.0023 0.0445 0.0077"/>
      </geometry>
    </collision>
  </link>
  <joint name="base_link_sharp_right_joint" type="fixed">
    <parent link="base_link"/>
    <child link="sharp_right"/>
    <origin xyz="0 -0.02 0.02" rpy="-1.568102 -0.001553 1.045641"/>
  </joint>
  <link name="sharp_left">
    <visual>
      <origin xyz="-0.0052 -0.0102 0" rpy="0 0 0"/>
      <geometry>
        <box size="0.01 0.03 0.0087"/>
      </geometry>
    </visual>
    <collision>
      <origin xyz="-0.0052 -0.0102 0" rpy="0 0 0"/>
      <geometry>
        <box size="0.01 0.03 0.0087"/>
      </geometry>
    </collision>
    <visual>
      <origin xyz="-0.0109 -0.0102 0" rpy="0 0 0"/>
      <geometry>
        <box size="0.0094 0.03 0.0131"/>
      </geometry>
    </visual>
    <collision>
      <origin xyz="-0.0109 -0.0102 0" rpy="0 0 0"/>
      <geometry>
        <box size="0.0094 0.03 0.0131"/>
      </geometry>
    </collision>
    <visual>
      <origin xyz="-0.0144 -0.0102 0" rpy="0 0 0"/>
      <geometry>
        <box size="0.0023 0.0445 0.0077"/>
      </geometry>
    </visual>
    <collision>
      <origin xyz="-0.0144 -0.0102 0" rpy="0 0 0"/>
      <geometry>
        <box size="0.0023 0.0445 0.0077"/>
      </geometry>
    </collision>
  </link>
  <joint name="base_link_sharp_left_joint" type="fixed">
    <parent link="base_link"/>
    <child link="sharp_left"/>
    <origin xyz="0 -0.02 0.02" rpy="-1.5708 0.000014 2.094405"/>
  </joint>
  <link name="gps">
  </link>
  <joint name="base_link_gps_joint" type="fixed">
    <parent link="base_link"/>
    <child link="gps"/>
    <origin xyz="0 0 0.03" rpy="0 0 0"/>
  </joint>
  <link name="gyro">
  </link>
  <joint name="base_link_gyro_joint" type="fixed">
    <parent link="base_link"/>
    <child link="gyro"/>
    <origin xyz="0 0 0.03" rpy="0 0 0"/>
  </joint>
  <link name="imu">
  </link>
  <joint name="base_link_imu_joint" type="fixed">
    <parent link="base_link"/>
    <child link="imu"/>
    <origin xyz="0 -0.03 0.03" rpy="0 0 0"/>
  </joint>
</robot>
