#VRML_SIM R2025a utf8

EXTERNPROTO "https://raw.githubusercontent.com/cyberbotics/webots/R2025a/projects/objects/backgrounds/protos/TexturedBackground.proto"
EXTERNPROTO "https://raw.githubusercontent.com/cyberbotics/webots/R2025a/projects/objects/backgrounds/protos/TexturedBackgroundLight.proto"
EXTERNPROTO "https://raw.githubusercontent.com/cyberbotics/webots/R2025a/projects/objects/floors/protos/RectangleArena.proto"
EXTERNPROTO "https://raw.githubusercontent.com/cyberbotics/webots/R2025a/projects/devices/sharp/protos/SharpGP2D120.proto"

WorldInfo {
}
Viewpoint {
  orientation -0.5774366550588885 -0.5616274801119171 0.5925719221980911 4.2210814202701465
  position -0.0016929017282186765 0.39167974878562617 5.896066476170032
}
TexturedBackground {
}
TexturedBackgroundLight {
}
RectangleArena {
  translation 0.01 0 0
  floorSize 3.048 3.048
  floorTileSize 0.61 0.61
}
Solid {
  translation 0.67 0.7 0
  children [
    Pose {
      translation 0 0 0.05
      children [
        DEF box Shape {
          appearance PBRAppearance {
            baseColor 1 0 0
            metalness 0
          }
          geometry Box {
            size 0.1 0.1 0.1
          }
        }
      ]
    }
  ]
  name "Red Box"
  boundingObject USE box
  physics Physics {
  }
}
Solid {
  translation -0.77 0.75 0
  children [
    Pose {
      translation 0 0 0.05
      children [
        DEF box Shape {
          appearance PBRAppearance {
            baseColor 0 0 1
            metalness 0
          }
          geometry Box {
            size 0.1 0.1 0.1
          }
        }
      ]
    }
  ]
  name "Blue Box"
  boundingObject USE box
  physics Physics {
  }
}
Pose {
  translation 1.29 0.25 0.0001
  children [
    Shape {
      appearance PBRAppearance {
        baseColor 1 0 0
        roughness 1
        metalness 0
      }
      geometry Plane {
        size 0.5 0.5
      }
    }
  ]
}
Pose {
  translation -1.27 0.25 0.0001
  children [
    Shape {
      appearance PBRAppearance {
        baseColor 0 0 1
        roughness 1
        metalness 0
      }
      geometry Plane {
        size 0.5 0.5
      }
    }
  ]
}
Pose {
  translation -1.27 -1.09 0.0001
  children [
    Shape {
      appearance PBRAppearance {
        baseColor 0 1 0
        roughness 1
        metalness 0
      }
      geometry Plane {
        size 0.5 0.5
      }
    }
  ]
}
Pose {
  translation 1.29 -1.11 0.0001
  children [
    Shape {
      appearance PBRAppearance {
        baseColor 1 1 0
        roughness 1
        metalness 0
      }
      geometry Plane {
        size 0.5 0.5
      }
    }
  ]
}
Solid {
  translation -0.16 -0.47 0
  children [
    Pose {
      translation 0 0 0.05
      children [
        DEF box Shape {
          appearance PBRAppearance {
            baseColor 0 1 0
            metalness 0
          }
          geometry Box {
            size 0.1 0.1 0.1
          }
        }
      ]
    }
  ]
  name "Green Box"
  boundingObject USE box
  physics Physics {
  }
}
Solid {
  translation 0.67 -0.52 0
  children [
    Pose {
      translation 0 0 0.05
      children [
        DEF box Shape {
          appearance PBRAppearance {
            baseColor 1 1 0
            metalness 0
          }
          geometry Box {
            size 0.1 0.1 0.1
          }
        }
      ]
    }
  ]
  name "Yellow Box"
  boundingObject USE box
  physics Physics {
  }
}
Robot {
  translation 0.163916 1.37981 -0.00282095
  rotation 0 0 -1 3.14
  children [
    RangeFinder {
      translation 4.2126e-07 0.09 0.11
      rotation 0 0 -1 -1.5708053071795867
    }
    Display {
      translation 0 0 0.11
    }
    Camera {
      translation -3.30588e-07 0.09 0.11
      rotation 0 0 1 1.5708
      fieldOfView 1.5
    }
    InertialUnit {
      translation 0 -0.03 0.03
      name "imu"
    }
    Gyro {
      translation 0 0 0.03
    }
    GPS {
      translation 0 0 0.03
    }
    SharpGP2D120 {
      translation -0.0989967 0.0789939 0.0199972
      rotation 0.28108510281518717 0.6785962482166418 -0.6786002482181049 -2.5935853071795862
      name "sharp_left"
    }
    SharpGP2D120 {
      translation 0.0991481 0.0788413 0.020112
      rotation -0.8629731098003907 -0.35707604543257354 0.35745504548079565 1.71434
      name "sharp_right"
    }
    SharpGP2D120 {
      translation -4.62331e-07 0.12 0.04
      rotation 0.5773489358556708 0.5773509358554485 0.5773509358554485 2.0944
      name "sharp_front"
    }
    SharpGP2D120 {
      translation -0.04 0.112 0.02
      rotation 0.5773522691882489 0.5773482691863839 -0.5773502691873165 -2.094395307179586
      name "sharp_front_left"
    }
    SharpGP2D120 {
      translation 0.04 0.112 0.02
      rotation 0.577351957236213 0.5773488930921109 -0.5773499572363613 -2.094395307179586
      name "sharp_front_right"
    }
    DEF body Pose {
      translation 0 0 0.049
      children [
        Shape {
          appearance PBRAppearance {
            baseColor 0 0.5 1
            roughness 1
            metalness 0
          }
          geometry Cylinder {
            height 0.08
            radius 0.117
          }
        }
      ]
    }
    HingeJoint {
      jointParameters HingeJointParameters {
        position -138.15041806853043
        anchor -0.105 -0.01 0.0126
      }
      device [
        PositionSensor {
          name "left wheel sensor"
        }
        RotationalMotor {
          name "left wheel motor"
        }
      ]
      endPoint Solid {
        translation -0.10499999999999998 -0.00999106252563567 0.012558917107145712
        rotation -0.3266369832980576 -0.8869139279066194 0.3266373610400323 1.6905123410164828
        children [
          DEF wheel Shape {
            appearance PBRAppearance {
              roughness 1
              metalness 0
            }
            geometry Cylinder {
              height 0.01
              radius 0.0125
            }
          }
        ]
        boundingObject USE wheel
        physics DEF wheel_physics Physics {
        }
      }
    }
    HingeJoint {
      jointParameters HingeJointParameters {
        position -230.7474216831195
        anchor 0.105 -0.01 0.0125
      }
      device [
        PositionSensor {
          name "right wheel sensor"
        }
        RotationalMotor {
          name "right wheel motor"
        }
      ]
      endPoint Solid {
        translation 0.10499999999999998 -0.009998949999852656 0.012523299999993359
        rotation 0.605705009743094 0.5159839383301476 0.6057078640379606 2.188888589492314
        children [
          USE wheel
        ]
        name "solid(1)"
        boundingObject USE wheel
        physics USE wheel_physics
      }
    }
    Pose {
      rotation 0 1 0 0
      children [
        Solid {
          translation 0 0.08 0.005
          rotation 0 1 0 -1.5707953071795862
          children [
            DEF caster_wheel Shape {
              appearance PBRAppearance {
              }
              geometry Sphere {
                radius 0.005
              }
            }
          ]
          name "solid(2)"
          boundingObject USE caster_wheel
          physics Physics {
            density 100
          }
        }
      ]
    }
  ]
  boundingObject USE body
  physics Physics {
    density 500
  }
  controller "Final_round_controller"
}
