#VRML_SIM R2025a utf8

EXTERNPROTO "https://raw.githubusercontent.com/cyberbotics/webots/R2025a/projects/objects/backgrounds/protos/TexturedBackground.proto"
EXTERNPROTO "https://raw.githubusercontent.com/cyberbotics/webots/R2025a/projects/objects/backgrounds/protos/TexturedBackgroundLight.proto"
EXTERNPROTO "https://raw.githubusercontent.com/cyberbotics/webots/R2025a/projects/objects/floors/protos/RectangleArena.proto"
EXTERNPROTO "https://raw.githubusercontent.com/cyberbotics/webots/R2025a/projects/devices/sharp/protos/SharpGP2D120.proto"
EXTERNPROTO "https://raw.githubusercontent.com/cyberbotics/webots/R2025a/projects/appearances/protos/Parquetry.proto"

WorldInfo {
}
Viewpoint {
  orientation -0.5799963153422786 -0.569386875883412 0.5825829209315257 4.214276426826617
  position 0.2929857969522455 1.3240565770403019 2.0166695386949827
}
TexturedBackground {
  skybox FALSE
}
TexturedBackgroundLight {
  castShadows FALSE
}
RectangleArena {
  translation 0.01 0 0
  floorSize 3.048 3.048
  floorTileSize 0.61 0.61
  floorAppearance Parquetry {
    type "dark strip"
  }
  wallHeight 0.5
}
Solid {
  translation 0.67 0.7 0
  children [
    Pose {
      translation 0 0 0.05
      children [
        DEF box Shape {
          appearance PBRAppearance {
            baseColor 1 0 0
            metalness 0
          }
          geometry Box {
            size 0.1 0.1 0.1
          }
        }
      ]
    }
  ]
  name "Red Box"
  boundingObject USE box
  physics Physics {
  }
}
Solid {
  translation -0.77 0.75 0
  children [
    Pose {
      translation 0 0 0.05
      children [
        DEF box Shape {
          appearance PBRAppearance {
            baseColor 0 0 1
            metalness 0
          }
          geometry Box {
            size 0.1 0.1 0.1
          }
        }
      ]
    }
  ]
  name "Blue Box"
  boundingObject USE box
  physics Physics {
  }
}
Pose {
  translation 1.29 0.25 0.0001
  children [
    Shape {
      appearance PBRAppearance {
        baseColor 1 0 0
        roughness 1
        metalness 0
      }
      geometry Plane {
        size 0.5 0.5
      }
    }
  ]
}
Pose {
  translation 1.53 0.25 0.2301
  rotation 0 1 0 -1.5707953071795862
  children [
    Shape {
      appearance PBRAppearance {
        baseColor 1 0 0
        roughness 1
        metalness 0
      }
      geometry Plane {
        size 0.5 0.5
      }
    }
  ]
}
Pose {
  translation -1.27 0.25 0.0001
  children [
    Shape {
      appearance PBRAppearance {
        baseColor 0 0 1
        roughness 1
        metalness 0
      }
      geometry Plane {
        size 0.5 0.5
      }
    }
  ]
}
Pose {
  translation -1.51 0.25 0.250101
  rotation 0 1 0 1.5708
  children [
    Shape {
      appearance PBRAppearance {
        baseColor 0 0 1
        metalness 0
      }
      geometry Plane {
        size 0.5 0.5
      }
    }
  ]
}
Pose {
  translation -1.27 -1.09 0.0001
  children [
    Shape {
      appearance PBRAppearance {
        baseColor 0 1 0
        roughness 1
        metalness 0
      }
      geometry Plane {
        size 0.5 0.5
      }
    }
  ]
}
Pose {
  translation -1.51 -1.09 0.240101
  rotation 0 1 0 1.5708
  children [
    Shape {
      appearance PBRAppearance {
        baseColor 0 1 0
        roughness 1
        metalness 0
      }
      geometry Plane {
        size 0.5 0.5
      }
    }
  ]
}
Pose {
  translation 1.29 -1.11 0.0001
  children [
    Shape {
      appearance PBRAppearance {
        baseColor 1 1 0
        roughness 1
        metalness 0
      }
      geometry Plane {
        size 0.5 0.5
      }
    }
  ]
}
Pose {
  translation 1.53 -1.11 0.2101
  rotation 0 1 0 -1.5707953071795862
  children [
    Shape {
      appearance PBRAppearance {
        baseColor 1 1 0
        roughness 1
        metalness 0
      }
      geometry Plane {
        size 0.5 0.5
      }
    }
  ]
}
Solid {
  translation -0.16 -0.47 0
  children [
    Pose {
      translation 0 0 0.05
      children [
        DEF box Shape {
          appearance PBRAppearance {
            baseColor 0 1 0
            metalness 0
          }
          geometry Box {
            size 0.1 0.1 0.1
          }
        }
      ]
    }
  ]
  name "Green Box"
  boundingObject USE box
  physics Physics {
  }
}
Solid {
  translation 0.67 -0.52 0
  children [
    Pose {
      translation 0 0 0.05
      children [
        DEF box Shape {
          appearance PBRAppearance {
            baseColor 1 1 0
            metalness 0
          }
          geometry Box {
            size 0.1 0.1 0.1
          }
        }
      ]
    }
  ]
  name "Yellow Box"
  boundingObject USE box
  physics Physics {
  }
}
Robot {
  translation 0.163916 1.37981 -0.00282095
  rotation 0 0 -1 3.14
  children [
    RangeFinder {
      translation 4.2126e-07 0.09 0.11
      rotation 0 0 -1 -1.5708053071795867
    }
    Display {
      translation 0 0 0.11
    }
    Camera {
      translation -3.30588e-07 0.09 0.11
      rotation 0 0 1 1.5708
      fieldOfView 0.8
    }
    InertialUnit {
      translation 0 -0.03 0.03
      name "imu"
    }
    Gyro {
      translation 0 0 0.03
    }
    GPS {
      translation 0 0 0.03
    }
    SharpGP2D120 {
      translation -0.0989967 0.0789939 0.0199972
      rotation 0.28108510281518717 0.6785962482166418 -0.6786002482181049 -2.5935853071795862
      name "sharp_left"
    }
    SharpGP2D120 {
      translation 0.0991481 0.0788413 0.020112
      rotation -0.8629731098003907 -0.35707604543257354 0.35745504548079565 1.71434
      name "sharp_right"
    }
    SharpGP2D120 {
      translation -4.62331e-07 0.12 0.04
      rotation 0.5773489358556708 0.5773509358554485 0.5773509358554485 2.0944
      name "sharp_front"
    }
    SharpGP2D120 {
      translation -0.04 0.112 0.02
      rotation 0.5773522691882489 0.5773482691863839 -0.5773502691873165 -2.094395307179586
      name "sharp_front_left"
    }
    SharpGP2D120 {
      translation 0.04 0.112 0.02
      rotation 0.577351957236213 0.5773488930921109 -0.5773499572363613 -2.094395307179586
      name "sharp_front_right"
    }
    DEF body Pose {
      translation 0 0 0.049
      children [
        Shape {
          appearance PBRAppearance {
            baseColor 0 0.5 1
            roughness 1
            metalness 0
          }
          geometry Cylinder {
            height 0.08
            radius 0.117
          }
        }
      ]
    }
    HingeJoint {
      jointParameters HingeJointParameters {
        position -138.15041806853043
        anchor -0.105 -0.01 0.0126
      }
      device [
        PositionSensor {
          name "left wheel sensor"
        }
        RotationalMotor {
          name "left wheel motor"
        }
      ]
      endPoint Solid {
        translation -0.10499999999999998 -0.00999106252563571 0.012558917107145691
        rotation -0.3266369832980686 -0.8869139279066046 0.32663736104006164 1.6905123410156169
        children [
          DEF wheel Shape {
            appearance PBRAppearance {
              roughness 1
              metalness 0
            }
            geometry Cylinder {
              height 0.01
              radius 0.0125
            }
          }
        ]
        boundingObject USE wheel
        physics DEF wheel_physics Physics {
        }
      }
    }
    HingeJoint {
      jointParameters HingeJointParameters {
        position -230.7474216831195
        anchor 0.105 -0.01 0.0125
      }
      device [
        PositionSensor {
          name "right wheel sensor"
        }
        RotationalMotor {
          name "right wheel motor"
        }
      ]
      endPoint Solid {
        translation 0.10499999999999998 -0.009998949999852609 0.012523299999993319
        rotation 0.6057050097429758 0.5159839383301941 0.6057078640380394 2.1888885894918784
        children [
          USE wheel
        ]
        name "solid(1)"
        boundingObject USE wheel
        physics USE wheel_physics
      }
    }
    Pose {
      rotation 0 1 0 0
      children [
        Solid {
          translation 0 0.08 0.005
          rotation 0 1 0 -1.5707953071795862
          children [
            DEF caster_wheel Shape {
              appearance PBRAppearance {
              }
              geometry Sphere {
                radius 0.005
              }
            }
          ]
          name "solid(2)"
          boundingObject USE caster_wheel
          physics Physics {
            density 100
          }
        }
      ]
    }
    Pose {
      translation 0 0.07 -0.005
      rotation 0 1 0 0
      children [
        Solid {
          translation -0.0899999 0.06 0.055
          rotation 0 1 0 -1.5707953071795862
          children [
            DEF Arm_left Shape {
              appearance PBRAppearance {
                roughness 1
                metalness 0
              }
              geometry Box {
                size 0.08 0.1 0.01
              }
            }
          ]
          name "solid(3)"
          boundingObject USE Arm_left
          physics Physics {
            density 100
          }
        }
      ]
    }
    Pose {
      translation 0.18 0.07 -0.005
      rotation 0 1 0 0
      children [
        Solid {
          translation -0.0899999 0.06 0.055
          rotation 0 1 0 -1.5707953071795862
          children [
            DEF Arm_right Shape {
              appearance PBRAppearance {
                roughness 1
                metalness 0
              }
              geometry Box {
                size 0.08 0.1 0.01
              }
            }
          ]
          name "solid(4)"
          boundingObject USE Arm_right
          physics Physics {
            density 100
          }
        }
      ]
    }
  ]
  boundingObject USE body
  physics Physics {
    density 500
  }
  controller "Final_round_controller"
}
